Workbook

Sheet FAME Persistence2
A1: 5 | B1: Deviations_ITFF_unw_v2
A2: Calc APP effect on IT | B2: $K$15 | D2: Refresh | E2: 0 | F2: FALSE
A3: Calc APP effect on IT | B3: $L$8 | D3: Refresh | E3: 0 | F3: FALSE
A4: Calc APP effect on IT | B4: $L$15 | D4: Refresh | E4: 0 | F4: FALSE
A5: Calc APP effect on IT | B5: $L$4 | D5: Refresh | E5: 0
A6: Calc APP effect on IT | B6: $L$11 | D6: Refresh | E6: 0

Sheet Calc APP effect on IT
B1: pure APP purchase impact / GDP | C1: from Nicolas db | F1: A | H1: Nominal PSPP holdings | K1: Start | L1: Nominal GDP
A2: 42064 | B2: =H2/M89 -> 0.0042487969 | C2: =-('[1]IT_Debt2GDP-Holdings'!$FC188-'[1]IT_Debt2GDP-Holdings'!$FB188)/100 -> 0.0080386366 | F2: 'IT' | G2: '31-Mar-2015' | H2: 6.8610537 | K2: End
A3: 42095 | B3: =H3/M90 -> 0.0084972007 | C3: =-('[1]IT_Debt2GDP-Holdings'!$FC189-'[1]IT_Debt2GDP-Holdings'!$FB189)/100 -> 0.01244809 | F3: 'IT' | G3: '30-Apr-2015' | H3: 13.748203 | K3: frequency
A4: 42125 | B4: =H4/M91 -> 0.012741855 | C4: =-('[1]IT_Debt2GDP-Holdings'!$FC190-'[1]IT_Debt2GDP-Holdings'!$FB190)/100 -> 0.016867942 | F4: 'IT' | G4: '31-May-2015' | H4: 20.656002
A5: 42156 | B5: =H5/M92 -> 0.016981073 | C5: =-('[1]IT_Debt2GDP-Holdings'!$FC191-'[1]IT_Debt2GDP-Holdings'!$FB191)/100 -> 0.021286305 | F5: 'IT' | G5: '30-Jun-2015' | H5: 27.581675 | L5: XXX0_W14_a_N_IT_YET
A6: 42186 | B6: =H6/M93 -> 0.021246047 | C6: =-('[1]IT_Debt2GDP-Holdings'!$FC192-'[1]IT_Debt2GDP-Holdings'!$FB192)/100 -> 0.025242208 | F6: 'IT' | G6: '31-Jul-2015' | H6: 34.586321 | L6: ="pct("&L5&")" -> pct(XXX0_W14_a_N_IT_YET)
A7: 42217 | B7: =H7/M94 -> 0.02549304 | C7: =-('[1]IT_Debt2GDP-Holdings'!$FC193-'[1]IT_Debt2GDP-Holdings'!$FB193)/100 -> 0.029196525 | F7: 'IT' | G7: '31-Aug-2015' | H7: 41.608971 | L7: ="lastvalue("&L5&")" -> lastvalue(XXX0_W14_a_N_IT_YET)
A8: 42248 | B8: =H8/M95 -> 0.029740058 | C8: =-('[1]IT_Debt2GDP-Holdings'!$FC194-'[1]IT_Debt2GDP-Holdings'!$FB194)/100 -> 0.033171322 | F8: 'IT' | G8: '30-Sep-2015' | H8: 48.665964 | L8: =[2]!FAMEdata(L6,L7,L7,0,"Annual","Down","Heading","Normal") -> Refresh
A9: 42278 | B9: =H9/M96 -> 0.033945325 | C9: =-('[1]IT_Debt2GDP-Holdings'!$FC195-'[1]IT_Debt2GDP-Holdings'!$FB195)/100 -> 0.036771441 | F9: 'IT' | G9: '31-Oct-2015' | H9: 55.690203 | K9: potential | L9: 0.43706993
A10: 42309 | B10: =H10/M97 -> 0.038161727 | C10: =-('[1]IT_Debt2GDP-Holdings'!$FC196-'[1]IT_Debt2GDP-Holdings'!$FB196)/100 -> 0.040411106 | F10: 'IT' | G10: '30-Nov-2015' | H10: 62.768146 | K10: nominal potential p.m. | L10: =1+(AVERAGE(I9:L9)+2)/1200 -> 1.0020309
A11: 42339 | B11: =H11/M98 -> 0.042357514 | C11: =-('[1]IT_Debt2GDP-Holdings'!$FC197-'[1]IT_Debt2GDP-Holdings'!$FB197)/100 -> 0.044012347 | F11: 'IT' | G11: '31-Dec-2015' | H11: 69.847578
A12: 42370 | B12: =H12/M99 -> 0.046561213 | C12: =-('[1]IT_Debt2GDP-Holdings'!$FC198-'[1]IT_Debt2GDP-Holdings'!$FB198)/100 -> 0.04797285 | F12: 'IT' | G12: '31-Jan-2016' | H12: 76.978612 | K12: Famedate | L12: XXX0_W14_a_N_IT_YEN
A13: 42401 | B13: =H13/M100 -> 0.05078694 | C13: =-('[1]IT_Debt2GDP-Holdings'!$FC199-'[1]IT_Debt2GDP-Holdings'!$FB199)/100 -> 0.051978633 | F13: 'IT' | G13: '29-Feb-2016' | H13: 84.175108 | L13: ="$eval_opt(""convert("&L12&",monthly,linear,average)"",""convert automatic off"")" -> $eval_opt("convert(XXX0_W14_a_N_IT_YEN,monthly,linear,average)","convert automatic off")
A14: 42430 | B14: =H14/M101 -> 0.055050322 | C14: =-('[1]IT_Debt2GDP-Holdings'!$FC200-'[1]IT_Debt2GDP-Holdings'!$FB200)/100 -> 0.055998125 | F14: 'IT' | G14: '31-Mar-2016' | H14: 91.469148 | L14: q4-2014
A15: 42461 | B15: =H15/M102 -> 0.059320798 | C15: =-('[1]IT_Debt2GDP-Holdings'!$FC201-'[1]IT_Debt2GDP-Holdings'!$FB201)/100 -> 0.059944062 | F15: 'IT' | G15: '30-Apr-2016' | H15: 98.814387 | K15: =[2]!FAMEdata(K12, L1,"lastvalue(XXX0_W22_a_N_FR_YEN)", 0,$B$3, "Down", "no heading", "Normal") -> Refresh | L15: =[2]!FAMEdata(L13,$B$1,$B$2,0,$B$3,"Down","no heading","Normal") -> Refresh
A16: 42491 | B16: =H16/M103 -> 0.063567729 | C16: =-('[1]IT_Debt2GDP-Holdings'!$FC202-'[1]IT_Debt2GDP-Holdings'!$FB202)/100 -> 0.063849112 | F16: 'IT' | G16: '31-May-2016' | H16: 106.15624 | K16: 39872 | L16: 1507322.4 | M16: =L16/1000 -> 1507.3224
A17: 42522 | B17: =H17/M104 -> 0.067840917 | C17: =-('[1]IT_Debt2GDP-Holdings'!$FC203-'[1]IT_Debt2GDP-Holdings'!$FB203)/100 -> 0.067797289 | F17: 'IT' | G17: '30-Jun-2016' | H17: 113.5778 | K17: 39903 | L17: 1509783.1 | M17: =L17/1000 -> 1509.7831
A18: 42552 | B18: =H18/M105 -> 0.072369888 | C18: =-('[1]IT_Debt2GDP-Holdings'!$FC204-'[1]IT_Debt2GDP-Holdings'!$FB204)/100 -> 0.071928774 | F18: 'IT' | G18: '31-Jul-2016' | H18: 121.46462 | K18: 39933 | L18: 1512327.2 | M18: =L18/1000 -> 1512.3272
A19: 42583 | B19: =H19/M106 -> 0.077257375 | C19: =-('[1]IT_Debt2GDP-Holdings'!$FC205-'[1]IT_Debt2GDP-Holdings'!$FB205)/100 -> 0.076421507 | F19: 'IT' | G19: '31-Aug-2016' | H19: 129.99812 | K19: 39964 | L19: 1514871.2 | M19: =L19/1000 -> 1514.8712
A20: 42614 | B20: =H20/M107 -> 0.082085708 | C20: =-('[1]IT_Debt2GDP-Holdings'!$FC206-'[1]IT_Debt2GDP-Holdings'!$FB206)/100 -> 0.080869526 | F20: 'IT' | G20: '30-Sep-2016' | H20: 138.46798 | K20: 39994 | L20: 1517415.3 | M20: =L20/1000 -> 1517.4153
A21: 42644 | B21: =H21/M108 -> 0.086071313 | C21: =-('[1]IT_Debt2GDP-Holdings'!$FC207-'[1]IT_Debt2GDP-Holdings'!$FB207)/100 -> 0.084421638 | F21: 'IT' | G21: '31-Oct-2016' | H21: 145.55334 | K21: 40025 | L21: 1519959.4 | M21: =L21/1000 -> 1519.9594
A22: 42675 | B22: =H22/M109 -> 0.089200864 | C22: =-('[1]IT_Debt2GDP-Holdings'!$FC208-'[1]IT_Debt2GDP-Holdings'!$FB208)/100 -> 0.087132471 | F22: 'IT' | G22: '30-Nov-2016' | H22: 151.221 | K22: 40056 | L22: 1522545.2 | M22: =L22/1000 -> 1522.5452
A23: 42705 | B23: =H23/M110 -> 0.091555902 | C23: =-('[1]IT_Debt2GDP-Holdings'!$FC209-'[1]IT_Debt2GDP-Holdings'!$FB209)/100 -> 0.089041338 | F23: 'IT' | G23: '31-Dec-2016' | H23: 155.5987 | K23: 40086 | L23: 1525089.3 | M23: =L23/1000 -> 1525.0893
A24: 42736 | B24: =H24/M111 -> 0.092870702 | C24: =-('[1]IT_Debt2GDP-Holdings'!$FC210-'[1]IT_Debt2GDP-Holdings'!$FB210)/100 -> 0.090050556 | F24: 'IT' | G24: '31-Jan-2017' | H24: 158.15022 | K24: 40117 | L24: 1527633.4 | M24: =L24/1000 -> 1527.6334
A25: 42767 | B25: =H25/M112 -> 0.093417935 | C25: =-('[1]IT_Debt2GDP-Holdings'!$FC211-'[1]IT_Debt2GDP-Holdings'!$FB211)/100 -> 0.090336813 | F25: 'IT' | G25: '28-Feb-2017' | H25: 159.40163 | K25: 40147 | L25: 1530177.5 | M25: =L25/1000 -> 1530.1775
A26: 42795 | B26: =H26/M113 -> 0.093188311 | C26: =-('[1]IT_Debt2GDP-Holdings'!$FC212-'[1]IT_Debt2GDP-Holdings'!$FB212)/100 -> 0.0897965 | F26: 'IT' | G26: '31-Mar-2017' | H26: 159.32919 | K26: 40178 | L26: 1532721.6 | M26: =L26/1000 -> 1532.7216
A27: 42826 | B27: =H27/M114 -> 0.092874882 | C27: =-('[1]IT_Debt2GDP-Holdings'!$FC213-'[1]IT_Debt2GDP-Holdings'!$FB213)/100 -> 0.089071271 | F27: 'IT' | G27: '30-Apr-2017' | H27: 159.11225 | K27: 40209 | L27: 1535307.4 | M27: =L27/1000 -> 1535.3074
... A35: 43070 | B35: =H35/M122 -> 0.087414313 | C35: =-('[1]IT_Debt2GDP-Holdings'!$FC221-'[1]IT_Debt2GDP-Holdings'!$FB221)/100 -> 0.079721263 | F35: 'IT' | G35: '31-Dec-2017' | H35: 152.18061 | K35: 40451 | L35: 1557379.4 | M35: =L35/1000 -> 1557.3794
A36: 43101 | B36: =H36/M123 -> 0.086479358 | F36: 'IT' | G36: '31-Jan-2018' | H36: 150.85533 | K36: 40482 | L36: 1560668.5 | M36: =L36/1000 -> 1560.6685
A37: 43132 | B37: =H37/M124 -> 0.085860086 | F37: 'IT' | G37: '28-Feb-2018' | H37: 150.0759 | K37: 40512 | L37: 1563957.7 | M37: =L37/1000 -> 1563.9577
A38: 43160 | B38: =H38/M125 -> 0.085661385 | F38: 'IT' | G38: '31-Mar-2018' | H38: 150.02933 | K38: 40543 | L38: 1567246.8 | M38: =L38/1000 -> 1567.2468
A39: 43191 | B39: =H39/M126 -> 0.083714164 | F39: 'IT' | G39: '30-Apr-2018' | H39: 146.91341 | K39: 40574 | L39: 1570589.9 | M39: =L39/1000 -> 1570.5899
A40: 43221 | B40: =H40/M127 -> 0.083527457 | F40: 'IT' | G40: '31-May-2018' | H40: 146.88018 | K40: 40602 | L40: 1573771.2 | M40: =L40/1000 -> 1573.7712
A41: 43252 | B41: =H41/M128 -> 0.081769419 | F41: 'IT' | G41: '30-Jun-2018' | H41: 144.07753 | K41: 40633 | L41: 1576952.5 | M41: =L41/1000 -> 1576.9525
A42: 43282 | B42: =H42/M129 -> 0.081603053 | F42: 'IT' | G42: '31-Jul-2018' | H42: 144.0732 | K42: 40663 | L42: 1580241.6 | M42: =L42/1000 -> 1580.2416
A43: 43313 | B43: =H43/M130 -> 0.08073369 | F43: 'IT' | G43: '31-Aug-2018' | H43: 142.8246 | K43: 40694 | L43: 1583530.7 | M43: =L43/1000 -> 1583.5307
A44: 43344 | B44: =H44/M131 -> 0.07871731 | F44: 'IT' | G44: '30-Sep-2018' | H44: 139.53716 | K44: 40724 | L44: 1586819.9 | M44: =L44/1000 -> 1586.8199
A45: 43374 | B45: =H45/M132 -> 0.078553755 | F45: 'IT' | G45: '31-Oct-2018' | H45: 139.52692 | K45: 40755 | L45: 1587726.1 | M45: =L45/1000 -> 1587.7261
A46: 43405 | B46: =H46/M133 -> 0.077010459 | F46: 'IT' | G46: '30-Nov-2018' | H46: 137.06047 | K46: 40786 | L46: 1585812.6 | M46: =L46/1000 -> 1585.8126
A47: 43435 | B47: =H47/M134 -> 0.075402367 | F47: 'IT' | G47: '31-Dec-2018' | H47: 134.46799 | K47: 40816 | L47: 1583923.9 | M47: =L47/1000 -> 1583.9239
...

Sheet Sentiment
B1: MOVE | C1: EPU | D1: VSTOXX | E1: VIX
A2: 39903 | B2: 117.9 | C2: 122.76371 | D2: 44.239925 | E2: 44.8
A3: 39933 | B3: 125.8 | C3: 108.54858 | D3: 39.971225 | E3: 38.06
A4: 39964 | B4: 165.4 | C4: 131.96498 | D4: 35.1929 | E4: 31.98
A5: 39994 | B5: 159 | C5: 73.35579 | D5: 31.387325 | E5: 29.14
A6: 40025 | B6: 138.5 | C6: 97.1195 | D6: 29.39998 | E6: 26.16
A7: 40056 | B7: 129.1 | C7: 57.65992 | D7: 28.1473 | E7: 25.34
A8: 40086 | B8: 110.7 | C8: 117.37453 | D8: 27.3079 | E8: 24.93
A9: 40117 | B9: 113.5 | C9: 88.23627 | D9: 26.73862 | E9: 24.25
A10: 40147 | B10: 88.9 | C10: 113.50382 | D10: 27.15255 | E10: 23.79
A11: 40178 | B11: 105 | C11: 99.86463 | D11: 25.166125 | E11: 21.24
A12: 40209 | B12: 86.3 | C12: 104.52817 | D12: 23.8753 | E12: 20.64
A13: 40237 | B13: 81.2 | C13: 106.47966 | D13: 26.817575 | E13: 22.54
... A70: 41973 | B70: 66.6 | C70: 159.69911 | D70: 19.7701 | E70: 13.41
A71: 42004 | B71: =AVERAGE(B70,B72) -> 77.45 | C71: 120.30161 | D71: 22.00195 | E71: 16.29
A72: 42035 | B72: 88.3 | C72: 99.27145 | D72: 26.29992 | E72: 19.12
A73: 42063 | B73: 91.4 | C73: 85.66958 | D73: 22.552925 | E73: 15.9
A74: 42094 | B74: 86.2 | C74: 109.05591 | D74: 19.097275 | E74: 14.81
A75: 42124 | B75: 71.6 | C75: 54.12688 | D75: 20.446825 | E75: 13.49
A76: 42155 | B76: 82.7 | C76: 146.40518 | D76: 22.1839 | E76: 13.34
A77: 42185 | B77: 84.3 | C77: 119.77798 | D77: 25.621575 | E77: 14.34
A78: 42216 | B78: 75.8 | C78: 142.43016 | D78: 24.21054 | E78: 14.35
A79: 42247 | B79: 91.1 | C79: 114.18858 | D79: 24.812525 | E79: 19.43
A80: 42277 | B80: 75.9 | C80: 124.55348 | D80: 31.20555 | E80: 24.38
A81: 42308 | B81: 73.1 | C81: 95.38362 | D81: 24.76742 | E81: 16.79
A82: 42338 | B82: 69.6 | C82: 95.95145 | D82: 22.77845 | E82: 16.21
A83: 42369 | B83: 65.5 | C83: 86.65267 | D83: 23.86645 | E83: 18.03
... A180: 45322 | B180: 100.23 | C180: 105.67807 | D180: 14.076825 | E180: 13.4

Sheet Deviations_Big4Fiscal
B1: APP | C1: PEPP
A2: 42064 | B2: =-'Calc APP effect on IT'!B2 -> -0.0042487969 | C2: -2.0191316e-08
A3: 42095 | B3: =-'Calc APP effect on IT'!B3 -> -0.0084972007 | C3: -4.3172603e-08
A4: 42125 | B4: =-'Calc APP effect on IT'!B4 -> -0.012741855 | C4: -7.0449606e-08
A5: 42156 | B5: =-'Calc APP effect on IT'!B5 -> -0.016981073 | C5: -1.0039174e-07
A6: 42186 | B6: =-'Calc APP effect on IT'!B6 -> -0.021246047 | C6: -1.9930108e-07
A7: 42217 | B7: =-'Calc APP effect on IT'!B7 -> -0.02549304 | C7: -3.1738072e-07
A8: 42248 | B8: =-'Calc APP effect on IT'!B8 -> -0.029740058 | C8: -4.6840505e-07
A9: 42278 | B9: =-'Calc APP effect on IT'!B9 -> -0.033945325 | C9: -3.8100665e-07
A10: 42309 | B10: =-'Calc APP effect on IT'!B10 -> -0.038161727 | C10: -2.587977e-07
A11: 42339 | B11: =-'Calc APP effect on IT'!B11 -> -0.042357514 | C11: -8.6632231e-08
A12: 42370 | B12: =-'Calc APP effect on IT'!B12 -> -0.046561213 | C12: 1.4261083e-07
A13: 42401 | B13: =-'Calc APP effect on IT'!B13 -> -0.05078694 | C13: 3.9894294e-07
... A422: 54848 | B422: =-'Calc APP effect on IT'!B422 -> 0 | C422: 1.2092268e-07

Sheet Deviations_Big4FF
B1: Mar-2015 | C1: Mar-2020 - PEPP only
A2: 42064 | B2: -0.0066321497 | C2: 0
A3: 42095 | B3: -0.01320175 | C3: 0
A4: 42125 | B4: -0.019821428 | C4: 0
A5: 42156 | B5: -0.02612239 | C5: 0
A6: 42186 | B6: -0.032367299 | C6: 0
A7: 42217 | B7: -0.039032529 | C7: 0
A8: 42248 | B8: -0.045316408 | C8: 0
A9: 42278 | B9: -0.051501809 | C9: 0
A10: 42309 | B10: -0.05806992 | C10: 0
A11: 42339 | B11: -0.064409942 | C11: 0
A12: 42370 | B12: -0.07072707 | C12: 0
A13: 42401 | B13: -0.076484278 | C13: 0
... A422: 54848 | B422: 0 | C422: -1.2092268e-05

Sheet FF_GDP_IT
B1: Debt-Eurosystem Holdings / GDP for IT
A2: 39903 | B2: 111.95278
A3: 39933 | B3: 112.49232
A4: 39964 | B4: 113.04985
A5: 39994 | B5: 113.58938
A6: 40025 | B6: 115.08662
A7: 40056 | B7: 116.58386
A8: 40086 | B8: 118.0328
A9: 40117 | B9: 118.11682
A10: 40147 | B10: 118.19813
A11: 40178 | B11: 118.28216
A12: 40209 | B12: 118.31803
A13: 40237 | B13: 118.35042
... A167: 44926 | B167: 111.34286

Sheet CISS
B1: CISS - Composite Indicator of Systemic Stress (rhs)
A2: 39903 | B2: 0.787098
A3: 39933 | B3: 0.677702
A4: 39964 | B4: 0.435694
A5: 39994 | B5: 0.661916
A6: 40025 | B6: 0.560251
A7: 40056 | B7: 0.409031
A8: 40086 | B8: 0.393609
A9: 40117 | B9: 0.497132
A10: 40147 | B10: 0.410576
A11: 40178 | B11: 0.263818
A12: 40209 | B12: 0.297293
A13: 40237 | B13: 0.322316
... A169: 44985 | B169: 0.21588

Sheet FF_IndividualCountries
A1: Date | B1: Free-float IT | C1: Free-float- FR | D1: Free-float- ES
A2: 39903 | B2: 0.65704554 | C2: 0.26900998 | D2: 0.13047035
A3: 39933 | B3: 0.64453818 | C3: 0.26156173 | D3: 0.14401042
A4: 39964 | B4: 0.65166807 | C4: 0.27699756 | D4: 0.15754052
A5: 39994 | B5: 0.63928277 | C5: 0.26934585 | D5: 0.17106066
A6: 40025 | B6: 0.64630798 | C6: 0.28494731 | D6: 0.18393456
A7: 40056 | B7: 0.63404403 | C7: 0.27709413 | D7: 0.1967978
A8: 40086 | B8: 0.64096519 | C8: 0.2928595 | D8: 0.20965269
A9: 40117 | B9: 0.62882187 | C9: 0.2848068 | D9: 0.21122524
A10: 40147 | B10: 0.64919404 | C10: 0.30189351 | D10: 0.21279664
A11: 40178 | B11: 0.63654706 | C11: 0.29351597 | D11: 0.21436688
A12: 40209 | B12: 0.65737908 | C12: 0.31087306 | D12: 0.22540719
A13: 40237 | B13: 0.64377572 | C13: 0.30205021 | D13: 0.23644353
... A502: 55122 | B502: 0.49999677 | C502: 0.32353568 | D502: 0.48659443

Sheet Big4_free-float(Dec-21)
A1: Date | B1: Nom_Eurosystem | C1: Nom_GOV | D1: Nom_ICPF | E1: Nom_OH | F1: Nom_pricesensitive | G1: Teny_Eurosystem | H1: Teny_GOV | I1: Teny_ICPF | J1: Teny_OH | K1: Teny_pricesensitive | L1: SHSTotal | M1: SHS10yTotal | N1: FreeFloat_teny | O1: FreeFloat_nom
A2: 39903 | B2: 241.77099 | C2: 66.17343 | D2: 646.25335 | E2: 798.85974 | F2: 2803.3924 | G2: 114.68087 | H2: 48.423248 | I2: 730.60504 | J2: 286.90679 | K2: 1628.5684 | L2: 4556.4499 | M2: 2809.1843 | N2: 0.57972999 | O2: 0.61525803
A3: 39933 | B3: 244.43045 | C3: 69.319821 | D3: 653.58794 | E3: 822.45596 | F3: 2844.0136 | G3: 115.54136 | H3: 49.856892 | I3: 745.31852 | J3: 294.70053 | K3: 1646.1353 | L3: 4632.9577 | M3: 2851.087 | N3: 0.57727685 | O3: 0.61375304
A4: 39964 | B4: 247.08991 | C4: 72.466212 | D4: 660.92254 | E4: 846.05218 | F4: 2884.6348 | G4: 116.40186 | H4: 51.290535 | I4: 760.032 | J4: 302.49427 | K4: 1663.7022 | L4: 4712.0158 | M4: 2894.3865 | N4: 0.57489555 | O4: 0.61229747
A5: 39994 | B5: 249.74936 | C5: 75.612604 | D5: 668.25713 | E5: 869.6484 | F5: 2925.256 | G5: 117.26235 | H5: 52.724179 | I5: 774.74548 | J5: 310.288 | K5: 1681.2692 | L5: 4788.5235 | M5: 2936.2892 | N5: 0.57258297 | O5: 0.61088893
A6: 40025 | B6: 250.82474 | C6: 77.348425 | D6: 666.82236 | E6: 875.0243 | F6: 2962.5076 | G6: 117.81988 | H6: 52.572379 | I6: 777.12333 | J6: 311.74864 | K6: 1709.1096 | L6: 4833.0057 | M6: 2968.7226 | N6: 0.57577303 | O6: 0.61303482
A7: 40056 | B7: 251.90012 | C7: 79.084247 | D7: 665.38758 | E7: 880.40021 | F7: 2999.7591 | G7: 118.37741 | H7: 52.42058 | I7: 779.50119 | J7: 313.20927 | K7: 1736.95 | L7: 4877.4879 | M7: 3001.156 | N7: 0.57889487 | O7: 0.61514198
A8: 40086 | B8: 252.9755 | C8: 80.820068 | D8: 663.95281 | E8: 885.77611 | F8: 3037.0107 | G8: 118.93494 | H8: 52.26878 | I8: 781.87905 | J8: 314.6699 | K8: 1764.7904 | L8: 4920.5351 | M8: 3032.5431 | N8: 0.58195065 | O8: 0.61721146
A9: 40117 | B9: 254.86638 | C9: 100.1385 | D9: 674.92369 | E9: 884.64711 | F9: 3048.1569 | G9: 119.60708 | H9: 64.380321 | I9: 790.55881 | J9: 314.24502 | K9: 1757.4869 | L9: 4963.1913 | M9: 3046.4274 | N9: 0.57692923 | O9: 0.61420938
A10: 40147 | B10: 256.75727 | C10: 119.45694 | D10: 685.89458 | E10: 883.51811 | F10: 3059.3032 | G10: 120.27922 | H10: 76.491862 | I10: 799.23857 | J10: 313.82013 | K10: 1750.1833 | L10: 5004.4714 | M10: 3059.8638 | N10: 0.57195288 | O10: 0.61125793
A11: 40178 | B11: 258.64815 | C11: 138.77538 | D11: 696.86546 | E11: 882.38911 | F11: 3070.4494 | G11: 120.95136 | H11: 88.603403 | I11: 807.91833 | J11: 313.39525 | K11: 1742.8798 | L11: 5047.1275 | M11: 3073.7481 | N11: 0.56702101 | O11: 0.60835582
A12: 40209 | B12: 262.52886 | C12: 136.71648 | D12: 707.81179 | E12: 899.62314 | F12: 3113.5858 | G12: 122.41471 | H12: 89.9881 | I12: 820.12913 | J12: 320.06071 | K12: 1772.9298 | L12: 5122.704 | M12: 3127.2483 | N12: 0.56724271 | O12: 0.60809062
A13: 40237 | B13: 266.40957 | C13: 134.65759 | D13: 718.75813 | E13: 916.85717 | F13: 3156.7222 | G13: 123.87807 | H13: 91.372797 | I13: 832.33994 | J13: 326.72616 | K13: 1802.9799 | L13: 5190.9667 | M13: 3175.5711 | N13: 0.56745718 | O13: 0.60783289
... A493: 54847 | B493: 346.36257 | C493: 554.54407 | D493: 2893.5077 | E493: 2070.6813 | F493: 7602.9311 | G493: 134.41232 | H493: 303.47911 | I493: 2499.8791 | J493: 709.63594 | K493: 3728.5368 | L493: 13468.027 | M493: 7375.9433 | N493: 0.50549966 | O493: 0.56451708
A494: 54878 | L494: 13480.07 | M494: 7380.435
A495: 54908 | L495: 13493.404 | M495: 7388.1503
A496: 54939 | L496: 13506.307 | M496: 7417.8104
A497: 54969 | L497: 13519.641 | M497: 7406.5826
A498: 55000 | L498: 13532.544 | M498: 7407.3056
A499: 55031 | L499: 13545.878 | M499: 7424.039
A500: 55061 | L500: 13559.211 | M500: 7450.8831
A501: 55092 | L501: 13572.115 | M501: 7481.3813
A502: 55122 | L502: 13585.449 | M502: 7484.2008
A503: 55153 | L503: 13598.352 | M503: 7481.3381
A504: 55184 | L504: 13611.686 | M504: 7496.2252
A505: 55212 | L505: 13625.019 | M505: 7498.0103
... A755: 62823 | L755: 16897.344 | M755: 9142.023

Sheet unweighted_IT_freefloat
A1: Date | B1: Nom_Eurosystem | C1: Nom_GOV | D1: Nom_ICPF | E1: Nom_OH | F1: Nom_pricesensitive | G1: Teny_Eurosystem | H1: Teny_GOV | I1: Teny_ICPF | J1: Teny_OH | K1: Teny_pricesensitive | L1: SHSTotal | M1: SHS10yTotal | N1: FreeFloat_teny | O1: FreeFloat_nom | P1: PSPP_Hold_Nominal | Q1: PSPP_Hold_teny_Nominal | R1: PEPPGOV_Hold_Nominal | S1: PEPPGOV_Hold_teny_Nominal | T1: NGDP
A2: 39903 | B2: 113.09065 | C2: 7.8200706 | D2: 204.23205 | E2: 78.894353 | F2: 1029.6811 | G2: 63.094321 | H2: 6.5864383 | I2: 211.30798 | J2: 24.540384 | K2: 665.71847 | L2: 1433.7182 | M2: 971.24759 | N2: 0.68542612 | O2: 0.71818931 | T2: 1567.1596
A3: 39933 | B3: 112.35402 | C3: 8.2048564 | D3: 208.49115 | E3: 82.356013 | F3: 1022.9099 | G3: 62.683348 | H3: 7.4202451 | I3: 217.84269 | J3: 25.617146 | K3: 666.83123 | L3: 1434.3159 | M3: 980.39465 | N3: 0.68016612 | O3: 0.71316916 | T3: 1569.6896
A4: 39964 | B4: 111.61739 | C4: 8.5896421 | D4: 212.75025 | E4: 85.817672 | F4: 1016.1386 | G4: 62.272375 | H4: 8.2540519 | I4: 224.3774 | J4: 26.693908 | K4: 667.94399 | L4: 1434.9136 | M4: 989.54172 | N4: 0.67500336 | O4: 0.70815318 | T4: 1572.2196
A5: 39994 | B5: 110.88076 | C5: 8.9744279 | D5: 217.00935 | E5: 89.279332 | F5: 1009.3673 | G5: 61.861402 | H5: 9.0878587 | I5: 230.91211 | J5: 27.77067 | K5: 669.05674 | L5: 1435.5112 | M5: 998.68878 | N5: 0.66993517 | O5: 0.70314139 | T5: 1574.7496
A6: 40025 | B6: 111.81057 | C6: 9.3093309 | D6: 219.07907 | E6: 90.49599 | F6: 1023.9755 | G6: 62.38015 | H6: 9.5267937 | I6: 231.60185 | J6: 28.149116 | K6: 678.35652 | L6: 1454.6705 | M6: 1010.0144 | N6: 0.67163052 | O6: 0.70392267 | T6: 1577.2796
A7: 40056 | B7: 112.74038 | C7: 9.6442339 | D7: 221.14878 | E7: 91.712649 | F7: 1038.5837 | G7: 62.898899 | H7: 9.9657287 | I7: 232.29159 | J7: 28.527563 | K7: 687.65629 | L7: 1473.8297 | M7: 1021.3401 | N7: 0.67328827 | O7: 0.70468364 | T7: 1579.8511
A8: 40086 | B8: 113.67018 | C8: 9.9791369 | D8: 223.2185 | E8: 92.929307 | F8: 1053.1919 | G8: 63.417647 | H8: 10.404664 | I8: 232.98133 | J8: 28.906009 | K8: 696.95607 | L8: 1492.989 | M8: 1032.6657 | N8: 0.67490966 | O8: 0.70542508 | T8: 1582.3811
A9: 40117 | B9: 113.92175 | C9: 10.631858 | D9: 226.45297 | E9: 92.729685 | F9: 1046.517 | G9: 63.557999 | H9: 10.727366 | I9: 235.82259 | J9: 28.843915 | K9: 698.01809 | L9: 1490.2533 | M9: 1036.97 | N9: 0.67313241 | O9: 0.70224104 | T9: 1584.9111
A10: 40147 | B10: 114.17332 | C10: 11.284579 | D10: 229.68744 | E10: 92.530062 | F10: 1039.8421 | G10: 63.69835 | H10: 11.050069 | I10: 238.66385 | J10: 28.781822 | K10: 699.08011 | L10: 1487.5175 | M10: 1041.2742 | N10: 0.67136985 | O10: 0.6990453 | T10: 1587.4412
A11: 40178 | B11: 114.42488 | C11: 11.9373 | D11: 232.92191 | E11: 92.330439 | F11: 1033.1673 | G11: 63.838701 | H11: 11.372771 | I11: 241.50511 | J11: 28.719729 | K11: 700.14213 | L11: 1484.7818 | M11: 1045.5784 | N11: 0.66962181 | O11: 0.69583777 | T11: 1589.9712
A12: 40209 | B12: 115.08239 | C12: 12.235238 | D12: 235.6451 | E12: 93.105268 | F12: 1033.8666 | G12: 64.205528 | H12: 11.772536 | I12: 243.04276 | J12: 28.960742 | K12: 706.45805 | L12: 1489.9346 | M12: 1054.4396 | N12: 0.66998436 | O12: 0.69390066 | T12: 1592.5427
A13: 40237 | B13: 115.73989 | C13: 12.533175 | D13: 238.36829 | E13: 93.880096 | F13: 1034.5659 | G13: 64.572355 | H13: 12.1723 | I13: 244.5804 | J13: 29.201755 | K13: 712.77398 | L13: 1495.0873 | M13: 1063.3008 | N13: 0.67034087 | O13: 0.6919769 | T13: 1594.9897
... A71: 42004 | B71: 207.93697 | C71: 18.386945 | D71: 340.25175 | E71: 64.154788 | F71: 1173.1051 | G71: 103.64788 | H71: 14.552754 | I71: 274.53642 | J71: 15.078524 | K71: 740.86924 | L71: 1803.8355 | M71: 1148.6848 | N71: 0.64497173 | O71: 0.65033926 | T71: 1638.8024
A72: 42035 | B72: 208.92128 | C72: 18.350549 | D72: 341.25413 | E72: 75.609697 | F72: 1178.1255 | G72: 103.61997 | H72: 14.603857 | I72: 276.8832 | J72: 16.264037 | K72: 753.78432 | L72: 1822.2611 | M72: 1165.1554 | N72: 0.64693888 | O72: 0.64651847 | T72: 1640.8076 | V72: Actual change in free-float | W72: Assumed change
A73: 42063 | B73: 207.7331 | C73: 18.314154 | D73: 342.25651 | E73: 87.064606 | F73: 1185.3184 | G73: 103.59206 | H73: 14.65496 | I73: 279.22998 | J73: 17.449551 | K73: 766.69941 | L73: 1840.6868 | M73: 1181.626 | N73: 0.64885119 | O73: 0.64395443 | T73: 1642.7159 | U73: =F73/T73 -> 0.7215602
A74: 42094 | B74: 215.00839 | C74: 18.277759 | D74: 343.25888 | E74: 98.519515 | F74: 1184.0478 | G74: 109.32282 | H74: 14.706063 | I74: 281.57675 | J74: 18.635064 | K74: 773.85582 | L74: 1859.1124 | M74: 1198.0965 | N74: 0.64590441 | O74: 0.63688879 | P74: 6.291 | Q74: 5.7405667 | T74: 1644.6241 | U74: =F74/T74 -> 0.71995043 | V74: =U74-$U$73 -> -0.001609772 | W74: -0.0038251902
A75: 42124 | B75: 219.20899 | C75: 18.337765 | D75: 342.98871 | E75: 107.86667 | F75: 1174.1077 | G75: 113.5487 | H75: 14.700201 | I75: 282.96999 | J75: 20.513344 | K75: 768.04694 | L75: 1862.5098 | M75: 1199.7792 | N75: 0.64015692 | O75: 0.63039007 | P75: 12.795 | Q75: 10.8335 | T75: 1646.597 | U75: =F75/T75 -> 0.71305104 | V75: =U75-$U$73 -> -0.008509159 | W75: -0.0077705716
A76: 42155 | B76: 225.90757 | C76: 18.397771 | D76: 342.71853 | E76: 117.21383 | F76: 1161.6696 | G76: 119.22321 | H76: 14.694338 | I76: 284.36323 | J76: 22.391624 | K76: 760.78944 | L76: 1865.9073 | M76: 1201.4618 | N76: 0.63321981 | O76: 0.62257627 | P76: 19.882 | Q76: 17.359092 | T76: 1648.5699 | U76: =F76/T76 -> 0.70465293 | V76: =U76-$U$73 -> -0.016907276 | W76: -0.01206015
A77: 42185 | B77: 228.66916 | C77: 18.457777 | D77: 342.44835 | E77: 126.56099 | F77: 1153.1685 | G77: 125.07055 | H77: 14.688475 | I77: 285.75646 | J77: 24.269903 | K77: 753.35911 | L77: 1869.3048 | M77: 1203.1445 | N77: 0.62615846 | O77: 0.616897 | P77: 27.087 | Q77: 24.057517 | T77: 1650.5428 | U77: =F77/T77 -> 0.69866015 | V77: =U77-$U$73 -> -0.022900049 | W77: -0.016410965
A78: 42216 | B78: 235.01307 | C78: 18.368036 | D78: 343.2682 | E78: 119.99353 | F78: 1154.4043 | G78: 134.32298 | H78: 14.513492 | I78: 284.46444 | J78: 23.935041 | K78: 746.16052 | L78: 1871.0472 | M78: 1203.3965 | N78: 0.62004546 | O78: 0.61698302 | P78: 34.3265 | Q78: 31.200758 | T78: 1653.3506 | U78: =F78/T78 -> 0.69822112 | V78: =U78-$U$73 -> -0.023339077 | W78: -0.020761779
A79: 42247 | B79: 238.30092 | C79: 18.278296 | D79: 344.08806 | E79: 113.42607 | F79: 1158.6962 | G79: 142.04442 | H79: 14.338509 | I79: 283.17242 | J79: 23.600179 | K79: 740.49291 | L79: 1872.7896 | M79: 1203.6484 | N79: 0.61520697 | O79: 0.6187007 | P79: 40.21605 | Q79: 36.813008 | T79: 1657.1976 | U79: =F79/T79 -> 0.69919012 | V79: =U79-$U$73 -> -0.022370078 | W79: -0.024267504
A80: 42277 | B80: 244.51584 | C80: 18.188555 | D80: 344.90792 | E80: 106.85861 | F80: 1160.061 | G80: 151.42802 | H80: 14.163526 | I80: 281.88041 | J80: 23.265317 | K80: 733.16316 | L80: 1874.532 | M80: 1203.9004 | N80: 0.60898987 | O80: 0.6188537 | P80: 47.32655 | Q80: 44.073191 | T80: 1660.9847 | U80: =F80/T80 -> 0.69841765 | V80: =U80-$U$73 -> -0.02314255 | W80: -0.028493068
A81: 42308 | B81: 252.11147 | C81: 17.645595 | D81: 356.6527 | E81: 105.01973 | F81: 1132.2288 | G81: 158.13849 | H81: 14.153481 | I81: 296.46338 | J81: 22.344689 | K81: 710.28515 | L81: 1863.6583 | M81: 1201.3852 | N81: 0.59122182 | O81: 0.60753025 | P81: 54.67025 | Q81: 51.088572 | T81: 1664.7718 | U81: =F81/T81 -> 0.6801105 | V81: =U81-$U$73 -> -0.041449704 | W81: -0.032839486
A82: 42338 | B82: 257.5774 | C82: 17.102635 | D82: 368.39748 | E82: 103.18085 | F82: 1106.5262 | G82: 164.89506 | H82: 14.143437 | I82: 311.04636 | J82: 21.424062 | K82: 687.36103 | L82: 1852.7846 | M82: 1198.87 | N82: 0.57334078 | O82: 0.59722334 | P82: 62.29425 | Q82: 58.150053 | T82: 1668.5589 | U82: =F82/T82 -> 0.66316281 | V82: =U82-$U$73 -> -0.058397389 | W82: -0.037334164
A83: 42369 | B83: 263.60834 | C83: 16.559675 | D83: 380.14227 | E83: 101.34197 | F83: 1080.2586 | G83: 170.35408 | H83: 14.133393 | I83: 325.62934 | J83: 20.503435 | K83: 665.73448 | L83: 1841.9109 | M83: 1196.3547 | N83: 0.55646913 | O83: 0.586488 | P83: 68.46825 | Q83: 63.893885 | T83: 1672.3459 | U83: =F83/T83 -> 0.64595404 | V83: =U83-$U$73 -> -0.075606166 | W83: -0.040941439
A84: 42400 | B84: 271.30814 | C84: 16.689392 | D84: 391.431 | E84: 103.78817 | F84: 1077.196 | G84: 176.13752 | H84: 14.023692 | I84: 333.57922 | J84: 20.633659 | K84: 661.59673 | L84: 1860.4127 | M84: 1205.9708 | N84: 0.54860094 | O84: 0.57900917 | P84: 75.789349 | Q84: 71.088391 | T84: 1676.1951 | U84: =F84/T84 -> 0.64264359 | V84: =U84-$U$73 -> -0.078916614 | W84: -0.045215112
A85: 42429 | B85: 279.04911 | C85: 16.819109 | D85: 402.71973 | E85: 106.23436 | F85: 1074.0923 | G85: 181.74665 | H85: 13.91399 | I85: 341.5291 | J85: 20.763884 | K85: 657.63329 | L85: 1878.9146 | M85: 1215.5869 | N85: 0.54100063 | O85: 0.57165573 | P85: 83.151599 | Q85: 78.108582 | T85: 1679.9201 | U85: =F85/T85 -> 0.63937106 | V85: =U85-$U$73 -> -0.082189142 | W85: -0.049497353
... A133: 43890 | B133: 481.68021 | C133: 16.663006 | D133: 412.02577 | E133: 50.446117 | F133: 1071.7347 | G133: 316.2306 | H133: 12.550127 | I133: 364.18768 | J133: 16.947735 | K133: 687.00119 | L133: 2032.5498 | M133: 1396.9173 | N133: 0.49179803 | O133: 0.52728581 | P133: 333.30912 | Q133: 236.77799 | T133: 1692.9461 | U133: =F133/T133 -> 0.63305892 | V133: =U133-$U$73 -> -0.088501284 | W133: -0.19688111
A134: 43921 | B134: 492.0079 | C134: 17.019553 | D134: 410.4225 | E134: 52.15309 | F134: 1063.6041 | G134: 329.75483 | H134: 12.804896 | I134: 367.61335 | J134: 18.307432 | K134: 676.60518 | L134: 2035.2072 | M134: 1405.0857 | N134: 0.48154016 | O134: 0.52260239 | P134: 343.95352 | Q134: 248.04992 | R134: 2.0532 | S134: 1.6754233 | T134: 1674.5286 | U134: =F134/T134 -> 0.6351663 | V134: =U134-$U$73 -> -0.086393898 | W134: -0.20662933
A135: 43951 | B135: 517.79599 | C135: 16.910957 | D135: 405.18837 | E135: 49.761936 | F135: 1080.3988 | G135: 345.05825 | H135: 12.683061 | I135: 363.57699 | J135: 17.052831 | K135: 684.42019 | L135: 2070.0561 | M135: 1422.7913 | N135: 0.48104046 | O135: 0.52191765 | P135: 354.29961 | Q135: 254.20397 | R135: 16.3957 | S135: 11.513647 | T135: 1655.804 | U135: =F135/T135 -> 0.65249195 | V135: =U135-$U$73 -> -0.069068253 | W135: -0.22387632
A136: 43982 | B136: 540.93459 | C136: 16.802362 | D136: 399.95425 | E136: 47.370781 | F136: 1099.843 | G136: 362.09886 | H136: 12.561226 | I136: 359.54063 | J136: 15.79823 | K136: 690.49801 | L136: 2104.9049 | M136: 1440.497 | N136: 0.47934708 | O136: 0.52251431 | P136: 356.97551 | Q136: 257.91689 | R136: 35.758924 | S136: 25.530174 | T136: 1637.0795 | U136: =F136/T136 -> 0.67183234 | V136: =U136-$U$73 -> -0.049727857 | W136: -0.23989943
A137: 44012 | B137: 563.98612 | C137: 16.693766 | D137: 394.72012 | E137: 44.979627 | F137: 1119.3742 | G137: 379.87193 | H137: 12.439391 | I137: 355.50427 | J137: 14.543629 | K137: 695.84337 | L137: 2139.7538 | M137: 1458.2026 | N137: 0.47719252 | O137: 0.52313223 | P137: 358.89314 | Q137: 261.51832 | R137: 55.793324 | S137: 40.39066 | T137: 1618.355 | U137: =F137/T137 -> 0.69167409 | V137: =U137-$U$73 -> -0.029886114 | W137: -0.2562395
A138: 44043 | B138: 585.91289 | C138: 16.787584 | D138: 392.62139 | E138: 46.296587 | F138: 1117.5702 | G138: 391.59828 | H138: 12.435152 | I138: 353.50787 | J138: 14.604178 | K138: 695.03026 | L138: 2159.1886 | M138: 1467.1757 | N138: 0.47371984 | O138: 0.51758803 | P138: 366.39094 | Q138: 264.67942 | R138: 69.373324 | S138: 48.999915 | T138: 1615.7544 | U138: =F138/T138 -> 0.69167081 | V138: =U138-$U$73 -> -0.029889389 | W138: -0.26969708
A139: 44074 | B139: 597.76595 | C139: 16.881402 | D139: 390.52266 | E139: 47.613546 | F139: 1125.8399 | G139: 396.28117 | H139: 12.430913 | I139: 351.51147 | J139: 14.664728 | K139: 701.2606 | L139: 2178.6234 | M139: 1476.1489 | N139: 0.47506089 | O139: 0.51676662 | P139: 367.99824 | Q139: 262.72874 | R139: 78.770124 | S139: 55.677518 | T139: 1631.1388 | U139: =F139/T139 -> 0.6902171 | V139: =U139-$U$73 -> -0.0313431 | W139: -0.27389966
A140: 44104 | B140: 610.08856 | C140: 16.97522 | D140: 388.42393 | E140: 48.930505 | F140: 1133.64 | G140: 405.46163 | H140: 12.426674 | I140: 349.51507 | J140: 14.725278 | K140: 702.99338 | L140: 2198.0583 | M140: 1485.122 | N140: 0.47335731 | O140: 0.51574613 | P140: 370.90337 | Q140: 264.81041 | R140: 89.353624 | S140: 62.820325 | T140: 1646.2926 | U140: =F140/T140 -> 0.68860179 | V140: =U140-$U$73 -> -0.032958412 | W140: -0.2795718
A141: 44135 | B141: 622.55156 | C141: 16.945724 | D141: 388.17361 | E141: 48.972013 | F141: 1115.8637 | G141: 414.43231 | H141: 12.648052 | I141: 349.597 | J141: 14.799473 | K141: 698.92398 | L141: 2192.5066 | M141: 1490.4008 | N141: 0.46895035 | O141: 0.50894429 | P141: 372.49178 | Q141: 267.09533 | R141: 99.785919 | S141: 69.853236 | T141: 1661.4464 | U141: =F141/T141 -> 0.67162185 | V141: =U141-$U$73 -> -0.049938354 | W141: -0.28425695
A142: 44165 | B142: 631.24587 | C142: 16.916228 | D142: 387.9233 | E142: 49.013521 | F142: 1101.8561 | G142: 424.86608 | H142: 12.869429 | I142: 349.67893 | J142: 14.873667 | K142: 693.3915 | L142: 2186.955 | M142: 1495.6796 | N142: 0.46359628 | O142: 0.50383117 | P142: 370.3191 | Q142: 271.86615 | R142: 110.2106 | S142: 75.863331 | T142: 1676.6003 | U142: =F142/T142 -> 0.65719666 | V142: =U142-$U$73 -> -0.064363536 | W142: -0.28660958
A143: 44196 | B143: 638.61007 | C143: 16.886732 | D143: 387.67299 | E143: 49.055028 | F143: 1089.1786 | G143: 429.62253 | H143: 13.090807 | I143: 349.76085 | J143: 14.947861 | K143: 693.53634 | L143: 2181.4034 | M143: 1500.9584 | N143: 0.46206233 | O143: 0.49930178 | P143: 369.1177 | Q143: 271.31396 | R143: 118.3339 | S143: 81.519112 | T143: 1691.7541 | U143: =F143/T143 -> 0.64381614 | V143: =U143-$U$73 -> -0.077744058 | W143: -0.28813384
A144: 44227 | B144: 650.48544 | C144: 17.042987 | D144: 387.32106 | E144: 51.60799 | F144: 1094.1217 | G144: 434.56179 | H144: 13.231862 | I144: 351.05609 | J144: 15.619008 | K144: 702.70522 | L144: 2200.5792 | M144: 1517.174 | N144: 0.4631672 | O144: 0.49719716 | P144: 372.54855 | Q144: 271.1481 | R144: 126.23866 | S144: 86.602728 | T144: 1707.1564 | U144: =F144/T144 -> 0.64090307 | V144: =U144-$U$73 -> -0.080657134 | W144: -0.29217429
...

Sheet Deviations_ITFF_unw
B1: Mar-2015 | C1: Mar-2020 - PEPP only
A2: 42064 | B2: =#REF!-#REF! -> #REF! | C2: 0
A3: 42095 | B3: =#REF!-#REF! -> #REF! | C3: 0
A4: 42125 | B4: =#REF!-#REF! -> #REF! | C4: 0
A5: 42156 | B5: =#REF!-#REF! -> #REF! | C5: 0
A6: 42186 | B6: =#REF!-#REF! -> #REF! | C6: 0
A7: 42217 | B7: =#REF!-#REF! -> #REF! | C7: 0
A8: 42248 | B8: =#REF!-#REF! -> #REF! | C8: 0
A9: 42278 | B9: =#REF!-#REF! -> #REF! | C9: 0
A10: 42309 | B10: =#REF!-#REF! -> #REF! | C10: 0
A11: 42339 | B11: =#REF!-#REF! -> #REF! | C11: 0
A12: 42370 | B12: =#REF!-#REF! -> #REF! | C12: 0
A13: 42401 | B13: =#REF!-#REF! -> #REF! | C13: 0
... A61: 43862 | B61: =#REF!-#REF! -> #REF! | C61: 0
A62: 43891 | B62: =#REF!-#REF! -> #REF! | C62: =(#REF!-#REF!) -> #REF!
A63: 43922 | B63: =#REF!-#REF! -> #REF! | C63: =(#REF!-#REF!) -> #REF!
A64: 43952 | B64: =#REF!-#REF! -> #REF! | C64: =(#REF!-#REF!) -> #REF!
A65: 43983 | B65: =#REF!-#REF! -> #REF! | C65: =(#REF!-#REF!) -> #REF!
A66: 44013 | B66: =#REF!-#REF! -> #REF! | C66: =(#REF!-#REF!) -> #REF!
A67: 44044 | B67: =#REF!-#REF! -> #REF! | C67: =(#REF!-#REF!) -> #REF!
A68: 44075 | B68: =#REF!-#REF! -> #REF! | C68: =(#REF!-#REF!) -> #REF!
A69: 44105 | B69: =#REF!-#REF! -> #REF! | C69: =(#REF!-#REF!) -> #REF!
A70: 44136 | B70: =#REF!-#REF! -> #REF! | C70: =(#REF!-#REF!) -> #REF!
A71: 44166 | B71: =#REF!-#REF! -> #REF! | C71: =(#REF!-#REF!) -> #REF!
A72: 44197 | B72: =#REF!-#REF! -> #REF! | C72: =(#REF!-#REF!) -> #REF!
A73: 44228 | B73: =#REF!-#REF! -> #REF! | C73: =(#REF!-#REF!) -> #REF!
... A422: 54848 | B422: =#REF!-#REF! -> #REF! | C422: =(#REF!-#REF!) -> #REF!

Sheet JSZ_OIS_Decompositions
B1: Data | L1: Fitted | V1: Expectations | AF1: Premia
B2: 1y | C2: 2y | D2: 3y | E2: 4y | F2: 5y | G2: 6y | H2: 7y | I2: 8y | J2: 9y | K2: 10y | L2: 1y | M2: 2y | N2: 3y | O2: 4y | P2: 5y | Q2: 6y | R2: 7y | S2: 8y | T2: 9y | U2: 10y | V2: 1y | W2: 2y | X2: 3y | Y2: 4y | Z2: 5y | AA2: 6y | AB2: 7y | AC2: 8y | AD2: 9y | AE2: 10y | AF2: 1y | AG2: 2y | AH2: 3y | AI2: 4y | AJ2: 5y | AK2: 6y | AL2: 7y | AM2: 8y | AN2: 9y | AO2: 10y
A3: 43908 | B3: -0.62300003 | C3: -0.60699999 | D3: -0.56 | E3: -0.48660001 | F3: -0.405 | G3: -0.338 | H3: -0.28099999 | I3: -0.24699999 | J3: -0.20299999 | K3: -0.162 | L3: -0.56094354 | M3: -0.56543499 | N3: -0.56128848 | O3: -0.53553122 | P3: -0.48877671 | Q3: -0.42544138 | R3: -0.35019091 | S3: -0.26688147 | T3: -0.1784212 | U3: -0.086915381 | V3: -0.42096201 | W3: -0.18070811 | X3: 0.042443961 | Y3: 0.22653821 | Z3: 0.37332362 | AA3: 0.49116775 | AB3: 0.58805186 | AC3: 0.66976261 | AD3: 0.74009025 | AE3: 0.8014791 | AF3: -0.13998154 | AG3: -0.38472688 | AH3: -0.60373247 | AI3: -0.76206946 | AJ3: -0.86210036 | AK3: -0.91660917 | AL3: -0.93824279 | AM3: -0.93664408 | AN3: -0.91851145 | AO3: -0.88839447
A4: 43909 | B4: -0.60350001 | C4: -0.57200003 | D4: -0.52999997 | E4: -0.47 | F4: -0.41100001 | G4: -0.34279999 | H4: -0.2843 | I4: -0.23810001 | J4: -0.19580001 | K4: -0.15700001 | L4: -0.54243088 | M4: -0.54298943 | N4: -0.54111314 | O4: -0.51926064 | P4: -0.47638625 | Q4: -0.41640234 | R4: -0.34390169 | S4: -0.2628088 | T4: -0.17613102 | U4: -0.086065702 | V4: -0.39774013 | W4: -0.15045196 | X4: 0.071344577 | Y4: 0.25166401 | Z4: 0.39470968 | AA4: 0.50953883 | AB4: 0.60413045 | AC4: 0.68409026 | AD4: 0.75303817 | AE4: 0.81330103 | AF4: -0.14469075 | AG4: -0.39253747 | AH4: -0.61245769 | AI4: -0.77092469 | AJ4: -0.8710959 | AK4: -0.92594117 | AL4: -0.94803214 | AM4: -0.94689906 | AN4: -0.92916918 | AO4: -0.89936674
A5: 43910 | B5: -0.62449998 | C5: -0.60900003 | D5: -0.5618 | E5: -0.51800001 | F5: -0.4691 | G5: -0.41569999 | H5: -0.3642 | I5: -0.3195 | J5: -0.28080001 | K5: -0.2462 | L5: -0.55213457 | M5: -0.56792426 | N5: -0.58115226 | O5: -0.571872 | P5: -0.53878653 | Q5: -0.48621348 | R5: -0.41926229 | S5: -0.34231064 | T5: -0.25871998 | U5: -0.17095158 | V5: -0.40492323 | W5: -0.1628969 | X5: 0.055439964 | Y5: 0.23416272 | Z5: 0.37689948 | AA5: 0.49214065 | AB5: 0.58748102 | AC5: 0.66831082 | AD5: 0.73814398 | AE5: 0.79926068 | AF5: -0.14721134 | AG5: -0.40502736 | AH5: -0.63659221 | AI5: -0.80603468 | AJ5: -0.91568601 | AK5: -0.9783541 | AL5: -1.0067433 | AM5: -1.0106214 | AN5: -0.99686396 | AO5: -0.97021222
B6: =B5-B3 -> -0.0014999509 | C6: =C5-C3 -> -0.0020000339 | D6: =D5-D3 -> -0.0018000007 | E6: =E5-E3 -> -0.031399995 | F6: =F5-F3 -> -0.064099997 | G6: =G5-G3 -> -0.077699989 | H6: =H5-H3 -> -0.083200008 | I6: =I5-I3 -> -0.072500005 | ... AO6: =AO5-AO3 -> -0.081817746

Sheet Deviations_CountryFF
B1: FR | D1: Compression | E1: FR | G1: Compression | H1: IT | J1: Compression | K1: IT | M1: Compression | N1: ES | P1: Compression | Q1: ES | S1: Compression
B2: Mar2015 - GDP projections | C2: Holdings Mar 2015 | E2: Mar2020 - GDP projections | F2: Holdings PEPP Mar 2020 | H2: Mar2015 - GDP projections | I2: Holdings Mar 2015 | K2: Mar2020 - GDP projections | L2: Holdings Mar 2020 | N2: Mar2015 - GDP projections | O2: Holdings Mar 2015 | Q2: Mar2020 - GDP projections | R2: Holdings Mar 2020
A3: 42094 | B3: =VLOOKUP($A3,[5]FR!$A:$R,18,1) -> 2164.7478 | C3: =VLOOKUP($A3,[5]FR!$A:$R,17,1) -> 6.8493034 | D3: =-C3/B3 -> -0.0031640191 | E3: =VLOOKUP($A3,[3]FR!$A:$T,20,1) -> 2186.1212 | F3: =VLOOKUP($A3,[3]FR!$A:$T,19,1) -> 0 | G3: =-F3/E3 -> 0 | H3: =VLOOKUP($A3,[5]IT!$A:$R,18,1) -> 1631.3648 | I3: =VLOOKUP($A3,[5]IT!$A:$R,17,1) -> 6.0968906 | J3: =-I3/H3 -> -0.0037372945 | K3: =VLOOKUP($A3,[3]IT!$A:$T,20,1) -> 1644.4971 | L3: =VLOOKUP($A3,[3]IT!$A:$T,19,1) -> 0 | M3: =-L3/K3 -> 0 | N3: =VLOOKUP(A3,[4]ES!$A:$P,16,1) -> 1081.4282 | Q3: =VLOOKUP(A3,[3]ES!$A:$P,16,1) -> 1064.553
A4: 42124 | B4: =VLOOKUP($A4,[5]FR!$A:$R,18,1) -> 2169.1305 | C4: =VLOOKUP($A4,[5]FR!$A:$R,17,1) -> 13.621166 | D4: =-C4/B4 -> -0.006279551 | E4: =VLOOKUP($A4,[3]FR!$A:$T,20,1) -> 2190.6125 | F4: =VLOOKUP($A4,[3]FR!$A:$T,19,1) -> 0 | G4: =-F4/E4 -> 0 | H4: =VLOOKUP($A4,[5]IT!$A:$R,18,1) -> 1633.3392 | I4: =VLOOKUP($A4,[5]IT!$A:$R,17,1) -> 12.119856 | J4: =-I4/H4 -> -0.0074202934 | K4: =VLOOKUP($A4,[3]IT!$A:$T,20,1) -> 1646.4984 | L4: =VLOOKUP($A4,[3]IT!$A:$T,19,1) -> 0 | M4: =-L4/K4 -> 0 | N4: =VLOOKUP(A4,[4]ES!$A:$P,16,1) -> 1084.6177 | Q4: =VLOOKUP(A4,[3]ES!$A:$P,16,1) -> 1069.0796
A5: 42155 | B5: =VLOOKUP($A5,[5]FR!$A:$R,18,1) -> 2173.5132 | C5: =VLOOKUP($A5,[5]FR!$A:$R,17,1) -> 20.504917 | D5: =-C5/B5 -> -0.009433997 | E5: =VLOOKUP($A5,[3]FR!$A:$T,20,1) -> 2195.1038 | F5: =VLOOKUP($A5,[3]FR!$A:$T,19,1) -> 0 | G5: =-F5/E5 -> 0 | H5: =VLOOKUP($A5,[5]IT!$A:$R,18,1) -> 1635.3136 | I5: =VLOOKUP($A5,[5]IT!$A:$R,17,1) -> 18.099452 | J5: =-I5/H5 -> -0.011067878 | K5: =VLOOKUP($A5,[3]IT!$A:$T,20,1) -> 1648.4998 | L5: =VLOOKUP($A5,[3]IT!$A:$T,19,1) -> 0 | M5: =-L5/K5 -> 0 | N5: =VLOOKUP(A5,[4]ES!$A:$P,16,1) -> 1087.8072 | Q5: =VLOOKUP(A5,[3]ES!$A:$P,16,1) -> 1073.6063
A6: 42185 | B6: =VLOOKUP($A6,[5]FR!$A:$R,18,1) -> 2177.8959 | C6: =VLOOKUP($A6,[5]FR!$A:$R,17,1) -> 27.284225 | D6: =-C6/B6 -> -0.012527791 | E6: =VLOOKUP($A6,[3]FR!$A:$T,20,1) -> 2199.5951 | F6: =VLOOKUP($A6,[3]FR!$A:$T,19,1) -> 0 | G6: =-F6/E6 -> 0 | H6: =VLOOKUP($A6,[5]IT!$A:$R,18,1) -> 1637.2879 | I6: =VLOOKUP($A6,[5]IT!$A:$R,17,1) -> 24.156454 | J6: =-I6/H6 -> -0.014753943 | K6: =VLOOKUP($A6,[3]IT!$A:$T,20,1) -> 1650.5012 | L6: =VLOOKUP($A6,[3]IT!$A:$T,19,1) -> 0 | M6: =-L6/K6 -> 0 | N6: =VLOOKUP(A6,[4]ES!$A:$P,16,1) -> 1090.9967 | Q6: =VLOOKUP(A6,[3]ES!$A:$P,16,1) -> 1078.133
A7: 42216 | B7: =VLOOKUP($A7,[5]FR!$A:$R,18,1) -> 2182.585 | C7: =VLOOKUP($A7,[5]FR!$A:$R,17,1) -> 34.076544 | D7: =-C7/B7 -> -0.015612929 | E7: =VLOOKUP($A7,[3]FR!$A:$T,20,1) -> 2202.9673 | F7: =VLOOKUP($A7,[3]FR!$A:$T,19,1) -> 0 | G7: =-F7/E7 -> 0 | H7: =VLOOKUP($A7,[5]IT!$A:$R,18,1) -> 1640.1238 | I7: =VLOOKUP($A7,[5]IT!$A:$R,17,1) -> 30.355011 | J7: =-I7/H7 -> -0.018507756 | K7: =VLOOKUP($A7,[3]IT!$A:$T,20,1) -> 1653.3018 | L7: =VLOOKUP($A7,[3]IT!$A:$T,19,1) -> 0 | M7: =-L7/K7 -> 0 | N7: =VLOOKUP(A7,[4]ES!$A:$P,16,1) -> 1094.0608 | Q7: =VLOOKUP(A7,[3]ES!$A:$P,16,1) -> 1081.7392
A8: 42247 | B8: =VLOOKUP($A8,[5]FR!$A:$R,18,1) -> 2187.7153 | C8: =VLOOKUP($A8,[5]FR!$A:$R,17,1) -> 40.979757 | D8: =-C8/B8 -> -0.01873176 | E8: =VLOOKUP($A8,[3]FR!$A:$T,20,1) -> 2205.0634 | F8: =VLOOKUP($A8,[3]FR!$A:$T,19,1) -> 0 | G8: =-F8/E8 -> 0 | H8: =VLOOKUP($A8,[5]IT!$A:$R,18,1) -> 1644.031 | I8: =VLOOKUP($A8,[5]IT!$A:$R,17,1) -> 36.43831 | J8: =-I8/H8 -> -0.022164004 | K8: =VLOOKUP($A8,[3]IT!$A:$T,20,1) -> 1657.0992 | L8: =VLOOKUP($A8,[3]IT!$A:$T,19,1) -> 0 | M8: =-L8/K8 -> 0 | N8: =VLOOKUP(A8,[4]ES!$A:$P,16,1) -> 1097.0259 | Q8: =VLOOKUP(A8,[3]ES!$A:$P,16,1) -> 1084.3097
A9: 42277 | B9: =VLOOKUP($A9,[5]FR!$A:$R,18,1) -> 2192.7637 | C9: =VLOOKUP($A9,[5]FR!$A:$R,17,1) -> 47.744811 | D9: =-C9/B9 -> -0.021773806 | E9: =VLOOKUP($A9,[3]FR!$A:$T,20,1) -> 2207.1228 | F9: =VLOOKUP($A9,[3]FR!$A:$T,19,1) -> 0 | G9: =-F9/E9 -> 0 | H9: =VLOOKUP($A9,[5]IT!$A:$R,18,1) -> 1647.8773 | I9: =VLOOKUP($A9,[5]IT!$A:$R,17,1) -> 42.480264 | J9: =-I9/H9 -> -0.025778778 | K9: =VLOOKUP($A9,[3]IT!$A:$T,20,1) -> 1660.8374 | L9: =VLOOKUP($A9,[3]IT!$A:$T,19,1) -> 0 | M9: =-L9/K9 -> 0 | N9: =VLOOKUP(A9,[4]ES!$A:$P,16,1) -> 1099.9429 | Q9: =VLOOKUP(A9,[3]ES!$A:$P,16,1) -> 1086.8363
A10: 42308 | B10: =VLOOKUP($A10,[5]FR!$A:$R,18,1) -> 2197.8121 | C10: =VLOOKUP($A10,[5]FR!$A:$R,17,1) -> 54.362492 | D10: =-C10/B10 -> -0.024734823 | E10: =VLOOKUP($A10,[3]FR!$A:$T,20,1) -> 2209.1822 | F10: =VLOOKUP($A10,[3]FR!$A:$T,19,1) -> 0 | G10: =-F10/E10 -> 0 | H10: =VLOOKUP($A10,[5]IT!$A:$R,18,1) -> 1651.7237 | I10: =VLOOKUP($A10,[5]IT!$A:$R,17,1) -> 48.481289 | J10: =-I10/H10 -> -0.029351937 | K10: =VLOOKUP($A10,[3]IT!$A:$T,20,1) -> 1664.5755 | L10: =VLOOKUP($A10,[3]IT!$A:$T,19,1) -> 0 | M10: =-L10/K10 -> 0 | N10: =VLOOKUP(A10,[4]ES!$A:$P,16,1) -> 1102.86 | Q10: =VLOOKUP(A10,[3]ES!$A:$P,16,1) -> 1089.363
A11: 42338 | B11: =VLOOKUP($A11,[5]FR!$A:$R,18,1) -> 2202.8604 | C11: =VLOOKUP($A11,[5]FR!$A:$R,17,1) -> 61.10601 | D11: =-C11/B11 -> -0.027739392 | E11: =VLOOKUP($A11,[3]FR!$A:$T,20,1) -> 2211.2417 | F11: =VLOOKUP($A11,[3]FR!$A:$T,19,1) -> 0 | G11: =-F11/E11 -> 0 | H11: =VLOOKUP($A11,[5]IT!$A:$R,18,1) -> 1655.57 | I11: =VLOOKUP($A11,[5]IT!$A:$R,17,1) -> 54.475262 | J11: =-I11/H11 -> -0.032904233 | K11: =VLOOKUP($A11,[3]IT!$A:$T,20,1) -> 1668.3137 | L11: =VLOOKUP($A11,[3]IT!$A:$T,19,1) -> 0 | M11: =-L11/K11 -> 0 | N11: =VLOOKUP(A11,[4]ES!$A:$P,16,1) -> 1105.777 | Q11: =VLOOKUP(A11,[3]ES!$A:$P,16,1) -> 1091.8897
A12: 42369 | B12: =VLOOKUP($A12,[5]FR!$A:$R,18,1) -> 2207.9088 | C12: =VLOOKUP($A12,[5]FR!$A:$R,17,1) -> 67.750161 | D12: =-C12/B12 -> -0.030685217 | E12: =VLOOKUP($A12,[3]FR!$A:$T,20,1) -> 2213.3011 | F12: =VLOOKUP($A12,[3]FR!$A:$T,19,1) -> 0 | G12: =-F12/E12 -> 0 | H12: =VLOOKUP($A12,[5]IT!$A:$R,18,1) -> 1659.4164 | I12: =VLOOKUP($A12,[5]IT!$A:$R,17,1) -> 60.558824 | J12: =-I12/H12 -> -0.03649405 | K12: =VLOOKUP($A12,[3]IT!$A:$T,20,1) -> 1672.0518 | L12: =VLOOKUP($A12,[3]IT!$A:$T,19,1) -> 0 | M12: =-L12/K12 -> 0 | N12: =VLOOKUP(A12,[4]ES!$A:$P,16,1) -> 1108.694 | Q12: =VLOOKUP(A12,[3]ES!$A:$P,16,1) -> 1094.4163
A13: 42400 | B13: =VLOOKUP($A13,[5]FR!$A:$R,18,1) -> 2213.04 | C13: =VLOOKUP($A13,[5]FR!$A:$R,17,1) -> 74.385087 | D13: =-C13/B13 -> -0.033612175 | E13: =VLOOKUP($A13,[3]FR!$A:$T,20,1) -> 2215.3943 | F13: =VLOOKUP($A13,[3]FR!$A:$T,19,1) -> 0 | G13: =-F13/E13 -> 0 | H13: =VLOOKUP($A13,[5]IT!$A:$R,18,1) -> 1663.3258 | I13: =VLOOKUP($A13,[5]IT!$A:$R,17,1) -> 66.538675 | J13: =-I13/H13 -> -0.040003393 | K13: =VLOOKUP($A13,[3]IT!$A:$T,20,1) -> 1675.8512 | L13: =VLOOKUP($A13,[3]IT!$A:$T,19,1) -> 0 | M13: =-L13/K13 -> 0 | N13: =VLOOKUP(A13,[4]ES!$A:$P,16,1) -> 1111.6588 | Q13: =VLOOKUP(A13,[3]ES!$A:$P,16,1) -> 1096.9844
A14: 42429 | B14: =VLOOKUP($A14,[5]FR!$A:$R,18,1) -> 2218.0056 | C14: =VLOOKUP($A14,[5]FR!$A:$R,17,1) -> 81.042977 | D14: =-C14/B14 -> -0.036538671 | E14: =VLOOKUP($A14,[3]FR!$A:$T,20,1) -> 2217.42 | F14: =VLOOKUP($A14,[3]FR!$A:$T,19,1) -> 0 | G14: =-F14/E14 -> 0 | H14: =VLOOKUP($A14,[5]IT!$A:$R,18,1) -> 1667.1091 | I14: =VLOOKUP($A14,[5]IT!$A:$R,17,1) -> 72.784022 | J14: =-I14/H14 -> -0.043658824 | K14: =VLOOKUP($A14,[3]IT!$A:$T,20,1) -> 1679.5281 | L14: =VLOOKUP($A14,[3]IT!$A:$T,19,1) -> 0 | M14: =-L14/K14 -> 0 | N14: =VLOOKUP(A14,[4]ES!$A:$P,16,1) -> 1114.5281 | Q14: =VLOOKUP(A14,[3]ES!$A:$P,16,1) -> 1099.4697
... A423: 54878 | B423: =VLOOKUP($A423,[5]FR!$A:$R,18,1) -> 5919.999 | C423: =VLOOKUP($A423,[5]FR!$A:$R,17,1) -> 0 | D423: =-C423/B423 -> 0 | E423: =VLOOKUP($A423,[3]FR!$A:$T,20,1) -> 5933.135 | F423: =VLOOKUP($A423,[3]FR!$A:$T,19,1) -> 0.030001019 | G423: =-F423/E423 -> -5.0565205e-06 | H423: =VLOOKUP($A423,[5]IT!$A:$R,18,1) -> 3956.5948 | I423: =VLOOKUP($A423,[5]IT!$A:$R,17,1) -> 0 | J423: =-I423/H423 -> 0 | K423: =VLOOKUP($A423,[3]IT!$A:$T,20,1) -> 3768.8726 | L423: =VLOOKUP($A423,[3]IT!$A:$T,19,1) -> 0.021503881 | M423: =-L423/K423 -> -5.7056534e-06 | N423: =VLOOKUP(A423,[4]ES!$A:$P,16,1) -> 2638.975 | Q423: =VLOOKUP(A423,[3]ES!$A:$P,16,1) -> 2651.5764
A424: 54908 | L424: =VLOOKUP($A424,[3]IT!$A:$T,19,1) -> 0.0179199
A425: 54939 | L425: =VLOOKUP($A425,[3]IT!$A:$T,19,1) -> 0.01433592
A426: 54969 | L426: =VLOOKUP($A426,[3]IT!$A:$T,19,1) -> 0.01075194
A427: 55000 | L427: =VLOOKUP($A427,[3]IT!$A:$T,19,1) -> 0.0071679602
A428: 55031 | L428: =VLOOKUP($A428,[3]IT!$A:$T,19,1) -> 0.0035839801
A429: 55061 | L429: =VLOOKUP($A429,[3]IT!$A:$T,19,1) -> 0
A430: 55092 | L430: =VLOOKUP($A430,[3]IT!$A:$T,19,1) -> 0
A431: 55122 | L431: =VLOOKUP($A431,[3]IT!$A:$T,19,1) -> 0
A432: 55153 | L432: =VLOOKUP($A432,[3]IT!$A:$T,19,1) -> 0
A433: 55184 | L433: =VLOOKUP($A433,[3]IT!$A:$T,19,1) -> 0

Sheet Deviations_ITFF_unw_v2
B1: Mar-2015 PSPP | C1: Mar-2020 - PEPP only
A2: 42064 | B2: =Deviations_CountryFF!J3 -> -0.0037372945 | C2: =Deviations_CountryFF!M3 -> 0
A3: 42095 | B3: =Deviations_CountryFF!J4 -> -0.0074202934 | C3: =Deviations_CountryFF!M4 -> 0
A4: 42125 | B4: =Deviations_CountryFF!J5 -> -0.011067878 | C4: =Deviations_CountryFF!M5 -> 0
A5: 42156 | B5: =Deviations_CountryFF!J6 -> -0.014753943 | C5: =Deviations_CountryFF!M6 -> 0
A6: 42186 | B6: =Deviations_CountryFF!J7 -> -0.018507756 | C6: =Deviations_CountryFF!M7 -> 0
A7: 42217 | B7: =Deviations_CountryFF!J8 -> -0.022164004 | C7: =Deviations_CountryFF!M8 -> 0
A8: 42248 | B8: =Deviations_CountryFF!J9 -> -0.025778778 | C8: =Deviations_CountryFF!M9 -> 0
A9: 42278 | B9: =Deviations_CountryFF!J10 -> -0.029351937 | C9: =Deviations_CountryFF!M10 -> 0
A10: 42309 | B10: =Deviations_CountryFF!J11 -> -0.032904233 | C10: =Deviations_CountryFF!M11 -> 0
A11: 42339 | B11: =Deviations_CountryFF!J12 -> -0.03649405 | C11: =Deviations_CountryFF!M12 -> 0
A12: 42370 | B12: =Deviations_CountryFF!J13 -> -0.040003393 | C12: =Deviations_CountryFF!M13 -> 0
A13: 42401 | B13: =Deviations_CountryFF!J14 -> -0.043658824 | C13: =Deviations_CountryFF!M14 -> 0
... A422: 54848 | B422: =Deviations_CountryFF!J423 -> 0 | C422: =Deviations_CountryFF!M423 -> -5.7056534e-06

Sheet PEPP_Holdings_Approx
B1: 43862 | E1: 43891 | H1: Difference | I1: Difference | J1: Difference
B2: ES | C2: FR | D2: IT | E2: ES | F2: FR | G2: IT | H2: ES | I2: FR | J2: IT
A3: Date | B3: Nom_Eurosystem | C3: Nom_Eurosystem | D3: Nom_Eurosystem | E3: Nom_Eurosystem | F3: Nom_Eurosystem | G3: Nom_Eurosystem
A4: 39903 | B4: 34.285558 | C4: 57.521939 | D4: 113.09065 | E4: 34.285558 | F4: 57.521939 | G4: 113.09065 | H4: =E4-B4 -> 0 | I4: =F4-C4 -> 0 | J4: =G4-D4 -> 0
A5: 39933 | B5: 36.16227 | C5: 57.521939 | D5: 113.09065 | E5: 36.16227 | F5: 57.521939 | G5: 113.09065 | H5: =E5-B5 -> 0 | I5: =F5-C5 -> 0 | J5: =G5-D5 -> 0
A6: 39964 | B6: 38.038982 | C6: 58.065253 | D6: 112.35402 | E6: 38.038982 | F6: 58.065253 | G6: 112.35402 | H6: =E6-B6 -> 0 | I6: =F6-C6 -> 0 | J6: =G6-D6 -> 0
A7: 39994 | B7: 39.915694 | C7: 58.065253 | D7: 112.35402 | E7: 39.915694 | F7: 58.065253 | G7: 112.35402 | H7: =E7-B7 -> 0 | I7: =F7-C7 -> 0 | J7: =G7-D7 -> 0
A8: 40025 | B8: 40.261816 | C8: 58.608566 | D8: 111.61739 | E8: 40.261816 | F8: 58.608566 | G8: 111.61739 | H8: =E8-B8 -> 0 | I8: =F8-C8 -> 0 | J8: =G8-D8 -> 0
A9: 40056 | B9: 40.607937 | C9: 58.608566 | D9: 111.61739 | E9: 40.607937 | F9: 58.608566 | G9: 111.61739 | H9: =E9-B9 -> 0 | I9: =F9-C9 -> 0 | J9: =G9-D9 -> 0
A10: 40086 | B10: 40.954058 | C10: 59.151879 | D10: 110.88076 | E10: 40.954058 | F10: 59.151879 | G10: 110.88076 | H10: =E10-B10 -> 0 | I10: =F10-C10 -> 0 | J10: =G10-D10 -> 0
A11: 40117 | B11: 43.072786 | C11: 59.151879 | D11: 110.88076 | E11: 43.072786 | F11: 59.151879 | G11: 110.88076 | H11: =E11-B11 -> 0 | I11: =F11-C11 -> 0 | J11: =G11-D11 -> 0
A12: 40147 | B12: 45.191514 | C12: 59.077113 | D12: 111.81057 | E12: 45.191514 | F12: 59.077113 | G12: 111.81057 | H12: =E12-B12 -> 0 | I12: =F12-C12 -> 0 | J12: =G12-D12 -> 0
A13: 40178 | B13: 47.310242 | C13: 59.077113 | D13: 111.81057 | E13: 47.310242 | F13: 59.077113 | G13: 111.81057 | H13: =E13-B13 -> 0 | I13: =F13-C13 -> 0 | J13: =G13-D13 -> 0
A14: 40209 | B14: 50.89159 | C14: 59.002347 | D14: 112.74038 | E14: 50.89159 | F14: 59.002347 | G14: 112.74038 | H14: =E14-B14 -> 0 | I14: =F14-C14 -> 0 | J14: =G14-D14 -> 0
A15: 40237 | B15: 54.472939 | C15: 59.002347 | D15: 112.74038 | E15: 54.472939 | F15: 59.002347 | G15: 112.74038 | H15: =E15-B15 -> 0 | I15: =F15-C15 -> 0 | J15: =G15-D15 -> 0
... A506: 55184 | B506: 38.083127 | C506: 61.81617 | D506: 124.50053 | E506: 37.842234 | F506: 62.575491 | G506: 126.10949 | H506: =E506-B506 -> -0.2408931 | I506: =F506-C506 -> 0.7593209 | J506: =G506-D506 -> 1.6089638
C507: 61.791919 | D507: 124.50053 | F507: 62.548011 | G507: 126.10949 | H507: =E507-B507 -> 0 | I507: =F507-C507 -> 0.7560911 | J507: =G507-D507 -> 1.6089638
C508: 55.243832 | D508: 124.50053 | F508: 55.328479 | G508: 126.10949 | H508: =E508-B508 -> 0 | I508: =F508-C508 -> 0.084647396 | J508: =G508-D508 -> 1.6089638
C509: 55.243832 | D509: 124.50053 | F509: 55.328479 | G509: 126.10949 | H509: =E509-B509 -> 0 | I509: =F509-C509 -> 0.084647396 | J509: =G509-D509 -> 1.6089638
C510: 55.243832 | D510: 124.50053 | F510: 55.328479 | G510: 126.10949 | H510: =E510-B510 -> 0 | I510: =F510-C510 -> 0.084647396 | J510: =G510-D510 -> 1.6089638
C511: 55.243832 | D511: 124.50053 | F511: 55.328479 | G511: 126.10949 | H511: =E511-B511 -> 0 | I511: =F511-C511 -> 0.084647396 | J511: =G511-D511 -> 1.6089638
C512: 55.243832 | D512: 122.86976 | F512: 55.328479 | G512: 124.25221 | H512: =E512-B512 -> 0 | I512: =F512-C512 -> 0.084647396 | J512: =G512-D512 -> 1.3824517
C513: 55.243832 | D513: 122.86976 | F513: 55.328479 | G513: 124.25221 | H513: =E513-B513 -> 0 | I513: =F513-C513 -> 0.084647396 | J513: =G513-D513 -> 1.3824517
C514: 55.243832 | D514: 122.86976 | F514: 55.328479 | G514: 124.25221 | H514: =E514-B514 -> 0 | I514: =F514-C514 -> 0.084647396 | J514: =G514-D514 -> 1.3824517
C515: 55.243832 | D515: 122.86976 | F515: 55.328479 | G515: 124.25221 | H515: =E515-B515 -> 0 | I515: =F515-C515 -> 0.084647396 | J515: =G515-D515 -> 1.3824517
C516: 55.243832 | D516: 122.86976 | F516: 55.328479 | G516: 124.25221

Sheet PEPP_Holdings_Approx (2)
B1: 43831 | E1: 43922 | H1: Difference | I1: Difference | J1: Difference
B2: ES | C2: FR | D2: IT | E2: ES | F2: FR | G2: IT | H2: ES | I2: FR | J2: IT
A3: Date | B3: Nom_Eurosystem | C3: Nom_Eurosystem | D3: Nom_Eurosystem | E3: Nom_Eurosystem | F3: Nom_Eurosystem | G3: Nom_Eurosystem
A4: 39903 | B4: 34.285558 | C4: 57.521939 | D4: 113.09065 | E4: 34.285558 | F4: 57.521939 | G4: 113.09065 | H4: =E4-B4 -> 0 | I4: =F4-C4 -> 0 | J4: =G4-D4 -> 0
A5: 39933 | B5: 36.16227 | C5: 57.521939 | D5: 113.09065 | E5: 36.16227 | F5: 57.521939 | G5: 113.09065 | H5: =E5-B5 -> 0 | I5: =F5-C5 -> 0 | J5: =G5-D5 -> 0
A6: 39964 | B6: 38.038982 | C6: 58.065253 | D6: 112.35402 | E6: 38.038982 | F6: 58.065253 | G6: 112.35402 | H6: =E6-B6 -> 0 | I6: =F6-C6 -> 0 | J6: =G6-D6 -> 0
A7: 39994 | B7: 39.915694 | C7: 58.065253 | D7: 112.35402 | E7: 39.915694 | F7: 58.065253 | G7: 112.35402 | H7: =E7-B7 -> 0 | I7: =F7-C7 -> 0 | J7: =G7-D7 -> 0
A8: 40025 | B8: 40.261816 | C8: 58.608566 | D8: 111.61739 | E8: 40.261816 | F8: 58.608566 | G8: 111.61739 | H8: =E8-B8 -> 0 | I8: =F8-C8 -> 0 | J8: =G8-D8 -> 0
A9: 40056 | B9: 40.607937 | C9: 58.608566 | D9: 111.61739 | E9: 40.607937 | F9: 58.608566 | G9: 111.61739 | H9: =E9-B9 -> 0 | I9: =F9-C9 -> 0 | J9: =G9-D9 -> 0
A10: 40086 | B10: 40.954058 | C10: 59.151879 | D10: 110.88076 | E10: 40.954058 | F10: 59.151879 | G10: 110.88076 | H10: =E10-B10 -> 0 | I10: =F10-C10 -> 0 | J10: =G10-D10 -> 0
A11: 40117 | B11: 43.072786 | C11: 59.151879 | D11: 110.88076 | E11: 43.072786 | F11: 59.151879 | G11: 110.88076 | H11: =E11-B11 -> 0 | I11: =F11-C11 -> 0 | J11: =G11-D11 -> 0
A12: 40147 | B12: 45.191514 | C12: 59.077113 | D12: 111.81057 | E12: 45.191514 | F12: 59.077113 | G12: 111.81057 | H12: =E12-B12 -> 0 | I12: =F12-C12 -> 0 | J12: =G12-D12 -> 0
A13: 40178 | B13: 47.310242 | C13: 59.077113 | D13: 111.81057 | E13: 47.310242 | F13: 59.077113 | G13: 111.81057 | H13: =E13-B13 -> 0 | I13: =F13-C13 -> 0 | J13: =G13-D13 -> 0
A14: 40209 | B14: 50.89159 | C14: 59.002347 | D14: 112.74038 | E14: 50.89159 | F14: 59.002347 | G14: 112.74038 | H14: =E14-B14 -> 0 | I14: =F14-C14 -> 0 | J14: =G14-D14 -> 0
A15: 40237 | B15: 54.472939 | C15: 59.002347 | D15: 112.74038 | E15: 54.472939 | F15: 59.002347 | G15: 112.74038 | H15: =E15-B15 -> 0 | I15: =F15-C15 -> 0 | J15: =G15-D15 -> 0
... A506: 55184 | B506: 38.328191 | C506: 62.81576 | D506: 121.51213 | E506: 41.444188 | F506: 71.393467 | G506: 138.21433 | H506: =E506-B506 -> 3.1159971 | I506: =F506-C506 -> 8.5777062 | J506: =G506-D506 -> 16.702202
C507: 62.791402 | D507: 121.51213 | F507: 70.891739 | G507: 136.42861 | H507: =E507-B507 -> 0 | I507: =F507-C507 -> 8.1003367 | J507: =G507-D507 -> 14.916478
C508: 56.737476 | D508: 121.51213 | F508: 61.678303 | G508: 135.96492 | H508: =E508-B508 -> 0 | I508: =F508-C508 -> 4.9408275 | J508: =G508-D508 -> 14.452794
C509: 56.737476 | D509: 121.51213 | F509: 60.915865 | G509: 135.42543 | H509: =E509-B509 -> 0 | I509: =F509-C509 -> 4.1783894 | J509: =G509-D509 -> 13.913302
C510: 56.737476 | D510: 121.51213 | F510: 60.199423 | G510: 134.92405 | H510: =E510-B510 -> 0 | I510: =F510-C510 -> 3.4619477 | J510: =G510-D510 -> 13.411919
C511: 56.737476 | D511: 121.51213 | F511: 59.812884 | G511: 134.92405 | H511: =E511-B511 -> 0 | I511: =F511-C511 -> 3.0754088 | J511: =G511-D511 -> 13.411919
C512: 56.737476 | D512: 121.51213 | F512: 59.098116 | G512: 131.99202 | H512: =E512-B512 -> 0 | I512: =F512-C512 -> 2.3606401 | J512: =G512-D512 -> 10.479892
C513: 56.737476 | D513: 121.51213 | F513: 58.437936 | G513: 131.50681 | H513: =E513-B513 -> 0 | I513: =F513-C513 -> 1.7004605 | J513: =G513-D513 -> 9.9946773
C514: 56.737476 | D514: 121.51213 | F514: 57.764559 | G514: 130.97702 | H514: =E514-B514 -> 0 | I514: =F514-C514 -> 1.0270834 | J514: =G514-D514 -> 9.4648889
C515: 56.737476 | D515: 121.51213 | F515: 57.562643 | G515: 130.79903 | H515: =E515-B515 -> 0 | I515: =F515-C515 -> 0.82516774 | J515: =G515-D515 -> 9.2868989
C516: 56.737476 | D516: 121.51213 | F516: 57.140352 | G516: 129.69085
